<?xml version="1.0" ?>
<robot name="Cyberdog_new_version" xmlns:xacro="http://www.ros.org/wiki/xacro">

<xacro:include filename="$(find Cyberdog_new_version_description)/urdf/materials.xacro" />
<xacro:include filename="$(find Cyberdog_new_version_description)/urdf/Cyberdog_new_version.trans" />
<xacro:include filename="$(find Cyberdog_new_version_description)/urdf/Cyberdog_new_version.gazebo" />
<link name="base_link">
  <inertial>
    <origin xyz="-0.005983169773680572 -0.0013186870120787198 0.3913121242716751" rpy="0 0 0"/>
    <mass value="79.15692100229101"/>
    <inertia ixx="0.481068" iyy="1.947481" izz="2.15732" ixy="-0.000886" iyz="-0.000126" ixz="-0.078421"/>
  </inertial>
  <visual>
    <origin xyz="0 0 0" rpy="0 0 0"/>
    <geometry>
      <mesh filename="package://Cyberdog_new_version_description/meshes/base_link.stl" scale="0.001 0.001 0.001"/>
    </geometry>
    <material name="silver"/>
  </visual>
  <collision>
    <origin xyz="0 0 0" rpy="0 0 0"/>
    <geometry>
      <mesh filename="package://Cyberdog_new_version_description/meshes/base_link.stl" scale="0.001 0.001 0.001"/>
    </geometry>
  </collision>
</link>

<link name="foot2_br_1">
  <inertial>
    <origin xyz="0.07006520870175942 3.644458188567512e-07 -0.0950206350944762" rpy="0 0 0"/>
    <mass value="0.7095711315921492"/>
    <inertia ixx="0.002276" iyy="0.003811" izz="0.001577" ixy="0.0" iyz="-0.0" ixz="0.001844"/>
  </inertial>
  <visual>
    <origin xyz="0.501914 -0.146118 -0.251186" rpy="0 0 0"/>
    <geometry>
      <mesh filename="package://Cyberdog_new_version_description/meshes/foot2_br_1.stl" scale="0.001 0.001 0.001"/>
    </geometry>
    <material name="silver"/>
  </visual>
  <collision>
    <origin xyz="0.501914 -0.146118 -0.251186" rpy="0 0 0"/>
    <geometry>
      <mesh filename="package://Cyberdog_new_version_description/meshes/foot2_br_1.stl" scale="0.001 0.001 0.001"/>
    </geometry>
  </collision>
</link>

<link name="foot1_fl_1">
  <inertial>
    <origin xyz="0.07006522133920697 4.7148385781681235e-07 -0.09501887615986912" rpy="0 0 0"/>
    <mass value="0.7095720022612411"/>
    <inertia ixx="0.002277" iyy="0.003812" izz="0.001577" ixy="0.0" iyz="-0.0" ixz="0.001844"/>
  </inertial>
  <visual>
    <origin xyz="-0.008786 -0.145932 -0.254438" rpy="0 0 0"/>
    <geometry>
      <mesh filename="package://Cyberdog_new_version_description/meshes/foot1_fl_1.stl" scale="0.001 0.001 0.001"/>
    </geometry>
    <material name="silver"/>
  </visual>
  <collision>
    <origin xyz="-0.008786 -0.145932 -0.254438" rpy="0 0 0"/>
    <geometry>
      <mesh filename="package://Cyberdog_new_version_description/meshes/foot1_fl_1.stl" scale="0.001 0.001 0.001"/>
    </geometry>
  </collision>
</link>

<link name="foot2_br_2">
  <inertial>
    <origin xyz="0.07006520870131583 3.644458205775969e-07 -0.09502063641320688" rpy="0 0 0"/>
    <mass value="0.7095711315921492"/>
    <inertia ixx="0.002276" iyy="0.003811" izz="0.001577" ixy="0.0" iyz="-0.0" ixz="0.001844"/>
  </inertial>
  <visual>
    <origin xyz="0.501914 0.148882 -0.251186" rpy="0 0 0"/>
    <geometry>
      <mesh filename="package://Cyberdog_new_version_description/meshes/foot2_br_2.stl" scale="0.001 0.001 0.001"/>
    </geometry>
    <material name="silver"/>
  </visual>
  <collision>
    <origin xyz="0.501914 0.148882 -0.251186" rpy="0 0 0"/>
    <geometry>
      <mesh filename="package://Cyberdog_new_version_description/meshes/foot2_br_2.stl" scale="0.001 0.001 0.001"/>
    </geometry>
  </collision>
</link>

<link name="foot1_fr_1">
  <inertial>
    <origin xyz="0.0700651623874154 4.7524155577516325e-07 -0.09502020850108295" rpy="0 0 0"/>
    <mass value="0.7095709358424983"/>
    <inertia ixx="0.002276" iyy="0.003811" izz="0.001577" ixy="0.0" iyz="-0.0" ixz="0.001844"/>
  </inertial>
  <visual>
    <origin xyz="-0.008786 0.149068 -0.254438" rpy="0 0 0"/>
    <geometry>
      <mesh filename="package://Cyberdog_new_version_description/meshes/foot1_fr_1.stl" scale="0.001 0.001 0.001"/>
    </geometry>
    <material name="silver"/>
  </visual>
  <collision>
    <origin xyz="-0.008786 0.149068 -0.254438" rpy="0 0 0"/>
    <geometry>
      <mesh filename="package://Cyberdog_new_version_description/meshes/foot1_fr_1.stl" scale="0.001 0.001 0.001"/>
    </geometry>
  </collision>
</link>

<link name="leg1_bl_1">
  <inertial>
    <origin xyz="-0.04327621629022177 0.020265222652791487 -0.025756193520784176" rpy="0 0 0"/>
    <mass value="5.623670463448883"/>
    <inertia ixx="0.009701" iyy="0.026697" izz="0.0184" ixy="-9e-06" iyz="-1.1e-05" ixz="-0.008656"/>
  </inertial>
  <visual>
    <origin xyz="0.315442 -0.126118 -0.382754" rpy="0 0 0"/>
    <geometry>
      <mesh filename="package://Cyberdog_new_version_description/meshes/leg1_bl_1.stl" scale="0.001 0.001 0.001"/>
    </geometry>
    <material name="silver"/>
  </visual>
  <collision>
    <origin xyz="0.315442 -0.126118 -0.382754" rpy="0 0 0"/>
    <geometry>
      <mesh filename="package://Cyberdog_new_version_description/meshes/leg1_bl_1.stl" scale="0.001 0.001 0.001"/>
    </geometry>
  </collision>
</link>

<link name="bol2_r_1">
  <inertial>
    <origin xyz="3.324335295928904e-07 3.572227312287346e-07 -0.0099739359106054" rpy="0 0 0"/>
    <mass value="0.15181620834766513"/>
    <inertia ixx="1.7e-05" iyy="1.7e-05" izz="2.1e-05" ixy="-0.0" iyz="-0.0" ixz="0.0"/>
  </inertial>
  <visual>
    <origin xyz="0.345101 0.148882 -0.063164" rpy="0 0 0"/>
    <geometry>
      <mesh filename="package://Cyberdog_new_version_description/meshes/bol2_r_1.stl" scale="0.001 0.001 0.001"/>
    </geometry>
    <material name="silver"/>
  </visual>
  <collision>
    <origin xyz="0.345101 0.148882 -0.063164" rpy="0 0 0"/>
    <geometry>
      <mesh filename="package://Cyberdog_new_version_description/meshes/bol2_r_1.stl" scale="0.001 0.001 0.001"/>
    </geometry>
  </collision>
</link>

<link name="bol2_l__1">
  <inertial>
    <origin xyz="3.3243397473681213e-07 3.572227285919549e-07 -0.009973934591875497" rpy="0 0 0"/>
    <mass value="0.1518162083476651"/>
    <inertia ixx="1.7e-05" iyy="1.7e-05" izz="2.1e-05" ixy="-0.0" iyz="-0.0" ixz="0.0"/>
  </inertial>
  <visual>
    <origin xyz="0.345101 -0.146118 -0.063164" rpy="0 0 0"/>
    <geometry>
      <mesh filename="package://Cyberdog_new_version_description/meshes/bol2_l__1.stl" scale="0.001 0.001 0.001"/>
    </geometry>
    <material name="silver"/>
  </visual>
  <collision>
    <origin xyz="0.345101 -0.146118 -0.063164" rpy="0 0 0"/>
    <geometry>
      <mesh filename="package://Cyberdog_new_version_description/meshes/bol2_l__1.stl" scale="0.001 0.001 0.001"/>
    </geometry>
  </collision>
</link>

<link name="bol1_r_1">
  <inertial>
    <origin xyz="3.3275021080192424e-07 4.682072707595797e-07 -0.009974111339621956" rpy="0 0 0"/>
    <mass value="0.1518162083476651"/>
    <inertia ixx="1.7e-05" iyy="1.7e-05" izz="2.1e-05" ixy="-0.0" iyz="-0.0" ixz="0.0"/>
  </inertial>
  <visual>
    <origin xyz="-0.165599 0.149068 -0.066417" rpy="0 0 0"/>
    <geometry>
      <mesh filename="package://Cyberdog_new_version_description/meshes/bol1_r_1.stl" scale="0.001 0.001 0.001"/>
    </geometry>
    <material name="silver"/>
  </visual>
  <collision>
    <origin xyz="-0.165599 0.149068 -0.066417" rpy="0 0 0"/>
    <geometry>
      <mesh filename="package://Cyberdog_new_version_description/meshes/bol1_r_1.stl" scale="0.001 0.001 0.001"/>
    </geometry>
  </collision>
</link>

<link name="bol1_l_1">
  <inertial>
    <origin xyz="3.3275563185442003e-07 4.6820506760525404e-07 -0.009974111337602273" rpy="0 0 0"/>
    <mass value="0.15181620834766513"/>
    <inertia ixx="1.7e-05" iyy="1.7e-05" izz="2.1e-05" ixy="-0.0" iyz="-0.0" ixz="0.0"/>
  </inertial>
  <visual>
    <origin xyz="-0.165599 -0.145932 -0.066417" rpy="0 0 0"/>
    <geometry>
      <mesh filename="package://Cyberdog_new_version_description/meshes/bol1_l_1.stl" scale="0.001 0.001 0.001"/>
    </geometry>
    <material name="silver"/>
  </visual>
  <collision>
    <origin xyz="-0.165599 -0.145932 -0.066417" rpy="0 0 0"/>
    <geometry>
      <mesh filename="package://Cyberdog_new_version_description/meshes/bol1_l_1.stl" scale="0.001 0.001 0.001"/>
    </geometry>
  </collision>
</link>

<link name="leg1_fr_1">
  <inertial>
    <origin xyz="-0.043276216372418436 -0.01973466501458032 -0.02575636937869935" rpy="0 0 0"/>
    <mass value="5.623670463448882"/>
    <inertia ixx="0.009701" iyy="0.026697" izz="0.0184" ixy="-9e-06" iyz="-1.1e-05" ixz="-0.008656"/>
  </inertial>
  <visual>
    <origin xyz="-0.195258 0.129068 -0.386007" rpy="0 0 0"/>
    <geometry>
      <mesh filename="package://Cyberdog_new_version_description/meshes/leg1_fr_1.stl" scale="0.001 0.001 0.001"/>
    </geometry>
    <material name="silver"/>
  </visual>
  <collision>
    <origin xyz="-0.195258 0.129068 -0.386007" rpy="0 0 0"/>
    <geometry>
      <mesh filename="package://Cyberdog_new_version_description/meshes/leg1_fr_1.stl" scale="0.001 0.001 0.001"/>
    </geometry>
  </collision>
</link>

<link name="leg1_fl_1">
  <inertial>
    <origin xyz="-0.04327621636698292 0.020265334983866068 -0.025756369376678745" rpy="0 0 0"/>
    <mass value="5.62367046344888"/>
    <inertia ixx="0.009701" iyy="0.026697" izz="0.0184" ixy="-9e-06" iyz="-1.1e-05" ixz="-0.008656"/>
  </inertial>
  <visual>
    <origin xyz="-0.195258 -0.125932 -0.386007" rpy="0 0 0"/>
    <geometry>
      <mesh filename="package://Cyberdog_new_version_description/meshes/leg1_fl_1.stl" scale="0.001 0.001 0.001"/>
    </geometry>
    <material name="silver"/>
  </visual>
  <collision>
    <origin xyz="-0.195258 -0.125932 -0.386007" rpy="0 0 0"/>
    <geometry>
      <mesh filename="package://Cyberdog_new_version_description/meshes/leg1_fl_1.stl" scale="0.001 0.001 0.001"/>
    </geometry>
  </collision>
</link>

<link name="motor2_bl_back_1">
  <inertial>
    <origin xyz="-0.06966547511359245 0.07519623218363408 1.2808463395463932e-07" rpy="0 0 0"/>
    <mass value="3.9545724305182866"/>
    <inertia ixx="0.005455" iyy="0.00436" izz="0.006263" ixy="0.000503" iyz="-0.0" ixz="0.0"/>
  </inertial>
  <visual>
    <origin xyz="0.240942 0.001382 -0.382754" rpy="0 0 0"/>
    <geometry>
      <mesh filename="package://Cyberdog_new_version_description/meshes/motor2_bl_back_1.stl" scale="0.001 0.001 0.001"/>
    </geometry>
    <material name="silver"/>
  </visual>
  <collision>
    <origin xyz="0.240942 0.001382 -0.382754" rpy="0 0 0"/>
    <geometry>
      <mesh filename="package://Cyberdog_new_version_description/meshes/motor2_bl_back_1.stl" scale="0.001 0.001 0.001"/>
    </geometry>
  </collision>
</link>

<link name="motor1_br_back__1">
  <inertial>
    <origin xyz="-0.06966547511381294 -0.07519552128081389 1.2741234328705886e-07" rpy="0 0 0"/>
    <mass value="3.954572430518811"/>
    <inertia ixx="0.005455" iyy="0.00436" izz="0.006263" ixy="-0.000503" iyz="-0.0" ixz="-0.0"/>
  </inertial>
  <visual>
    <origin xyz="0.240942 0.001382 -0.382754" rpy="0 0 0"/>
    <geometry>
      <mesh filename="package://Cyberdog_new_version_description/meshes/motor1_br_back__1.stl" scale="0.001 0.001 0.001"/>
    </geometry>
    <material name="silver"/>
  </visual>
  <collision>
    <origin xyz="0.240942 0.001382 -0.382754" rpy="0 0 0"/>
    <geometry>
      <mesh filename="package://Cyberdog_new_version_description/meshes/motor1_br_back__1.stl" scale="0.001 0.001 0.001"/>
    </geometry>
  </collision>
</link>

<link name="leg1_br_1">
  <inertial>
    <origin xyz="-0.04327621629066747 -0.019734777347206384 -0.025756194839514357" rpy="0 0 0"/>
    <mass value="5.623670463448881"/>
    <inertia ixx="0.009701" iyy="0.026697" izz="0.0184" ixy="-9e-06" iyz="-1.1e-05" ixz="-0.008656"/>
  </inertial>
  <visual>
    <origin xyz="0.315442 0.128882 -0.382754" rpy="0 0 0"/>
    <geometry>
      <mesh filename="package://Cyberdog_new_version_description/meshes/leg1_br_1.stl" scale="0.001 0.001 0.001"/>
    </geometry>
    <material name="silver"/>
  </visual>
  <collision>
    <origin xyz="0.315442 0.128882 -0.382754" rpy="0 0 0"/>
    <geometry>
      <mesh filename="package://Cyberdog_new_version_description/meshes/leg1_br_1.stl" scale="0.001 0.001 0.001"/>
    </geometry>
  </collision>
</link>

<link name="motor1_bl_1">
  <inertial>
    <origin xyz="0.07105512711326509 0.07516263480741354 -0.019999325403253276" rpy="0 0 0"/>
    <mass value="3.9597418607827"/>
    <inertia ixx="0.005468" iyy="0.004405" izz="0.00631" ixy="-0.000514" iyz="0.0" ixz="-0.0"/>
  </inertial>
  <visual>
    <origin xyz="-0.119258 0.001568 -0.406007" rpy="0 0 0"/>
    <geometry>
      <mesh filename="package://Cyberdog_new_version_description/meshes/motor1_bl_1.stl" scale="0.001 0.001 0.001"/>
    </geometry>
    <material name="silver"/>
  </visual>
  <collision>
    <origin xyz="-0.119258 0.001568 -0.406007" rpy="0 0 0"/>
    <geometry>
      <mesh filename="package://Cyberdog_new_version_description/meshes/motor1_bl_1.stl" scale="0.001 0.001 0.001"/>
    </geometry>
  </collision>
</link>

<link name="motor1_br_1">
  <inertial>
    <origin xyz="0.07105512711142445 -0.07516169901405914 -0.019999325404139845" rpy="0 0 0"/>
    <mass value="3.9597418606976182"/>
    <inertia ixx="0.005468" iyy="0.004405" izz="0.00631" ixy="0.000514" iyz="-0.0" ixz="-0.0"/>
  </inertial>
  <visual>
    <origin xyz="-0.119258 0.001568 -0.406007" rpy="0 0 0"/>
    <geometry>
      <mesh filename="package://Cyberdog_new_version_description/meshes/motor1_br_1.stl" scale="0.001 0.001 0.001"/>
    </geometry>
    <material name="silver"/>
  </visual>
  <collision>
    <origin xyz="-0.119258 0.001568 -0.406007" rpy="0 0 0"/>
    <geometry>
      <mesh filename="package://Cyberdog_new_version_description/meshes/motor1_br_1.stl" scale="0.001 0.001 0.001"/>
    </geometry>
  </collision>
</link>

<joint name="Revolute 5" type="continuous">
  <origin xyz="-0.186472 0.02 -0.131568" rpy="0 0 0"/>
  <parent link="leg1_bl_1"/>
  <child link="foot2_br_1"/>
  <axis xyz="-0.0 -1.0 -0.0"/>
</joint>

<joint name="Revolute 6" type="continuous">
  <origin xyz="-0.186472 0.02 -0.131569" rpy="0 0 0"/>
  <parent link="leg1_fl_1"/>
  <child link="foot1_fl_1"/>
  <axis xyz="-0.0 -1.0 -0.0"/>
</joint>

<joint name="Revolute 7" type="continuous">
  <origin xyz="-0.186472 -0.02 -0.131568" rpy="0 0 0"/>
  <parent link="leg1_br_1"/>
  <child link="foot2_br_2"/>
  <axis xyz="0.0 1.0 0.0"/>
</joint>

<joint name="Revolute 8" type="continuous">
  <origin xyz="-0.186472 -0.02 -0.131569" rpy="0 0 0"/>
  <parent link="leg1_fr_1"/>
  <child link="foot1_fr_1"/>
  <axis xyz="0.0 1.0 0.0"/>
</joint>

<joint name="Revolute 9" type="continuous">
  <origin xyz="-0.0745 0.1275 0.0" rpy="0 0 0"/>
  <parent link="motor2_bl_back_1"/>
  <child link="leg1_bl_1"/>
  <axis xyz="0.0 1.0 0.0"/>
</joint>

<joint name="Rigid 29" type="fixed">
  <origin xyz="0.156813 0.0 -0.188022" rpy="0 0 0"/>
  <parent link="foot2_br_2"/>
  <child link="bol2_r_1"/>
</joint>

<joint name="Rigid 30" type="fixed">
  <origin xyz="0.156813 0.0 -0.188022" rpy="0 0 0"/>
  <parent link="foot2_br_1"/>
  <child link="bol2_l__1"/>
</joint>

<joint name="Rigid 31" type="fixed">
  <origin xyz="0.156813 0.0 -0.188021" rpy="0 0 0"/>
  <parent link="foot1_fr_1"/>
  <child link="bol1_r_1"/>
</joint>

<joint name="Rigid 32" type="fixed">
  <origin xyz="0.156813 0.0 -0.188021" rpy="0 0 0"/>
  <parent link="foot1_fl_1"/>
  <child link="bol1_l_1"/>
</joint>

<joint name="Revolute 33" type="continuous">
  <origin xyz="0.076 -0.1275 -0.02" rpy="0 0 0"/>
  <parent link="motor1_br_1"/>
  <child link="leg1_fr_1"/>
  <axis xyz="-0.0 -1.0 -0.0"/>
</joint>

<joint name="Revolute 34" type="continuous">
  <origin xyz="0.076 0.1275 -0.02" rpy="0 0 0"/>
  <parent link="motor1_bl_1"/>
  <child link="leg1_fl_1"/>
  <axis xyz="0.0 1.0 0.0"/>
</joint>

<joint name="Revolute 35" type="continuous">
  <origin xyz="-0.240942 -0.001382 0.382754" rpy="0 0 0"/>
  <parent link="base_link"/>
  <child link="motor2_bl_back_1"/>
  <axis xyz="-1.0 0.0 -0.0"/>
</joint>

<joint name="Revolute 36" type="continuous">
  <origin xyz="-0.240942 -0.001382 0.382754" rpy="0 0 0"/>
  <parent link="base_link"/>
  <child link="motor1_br_back__1"/>
  <axis xyz="-1.0 0.0 -0.0"/>
</joint>

<joint name="Revolute 37" type="continuous">
  <origin xyz="-0.0745 -0.1275 0.0" rpy="0 0 0"/>
  <parent link="motor1_br_back__1"/>
  <child link="leg1_br_1"/>
  <axis xyz="-0.0 -1.0 -0.0"/>
</joint>

<joint name="Revolute 40" type="continuous">
  <origin xyz="0.119258 -0.001568 0.406007" rpy="0 0 0"/>
  <parent link="base_link"/>
  <child link="motor1_bl_1"/>
  <axis xyz="1.0 0.0 0.0"/>
</joint>

<joint name="Revolute 41" type="continuous">
  <origin xyz="0.119258 -0.001568 0.406007" rpy="0 0 0"/>
  <parent link="base_link"/>
  <child link="motor1_br_1"/>
  <axis xyz="1.0 0.0 0.0"/>
</joint>

</robot>
